<?xml version="1.0"?>
<robot xmlns:xacro="http://www.ros.org/wiki/xacro"  name="robot">
    <link name="base_link">
    </link>
    <link name="chassis">
        <visual>
            <origin xyz="0.15 0 0.075" rpy="0 0 0"/>
            <geometry>
                <box size="0.3 0.3 0.15"/>
            </geometry>
            <material name="black"/>
        </visual>
        <collision>
            <origin xyz="0.15 0 0.075" rpy="0 0 0"/>
            <geometry>
                <box size="0.3 0.3 0.15"/>
            </geometry> 
        </collision>
    </link>
    <joint name="chassis_joint" type="fixed">
        <parent link="base_link"/>
        <child link="chassis"/>
        <origin xyz="-0.1 0 0"/>
    </joint>
    
    <!-- LEFT WHEEL -->

    <joint name="left_wheel_joint" type="continuous">
        <parent link="base_link"/>
        <child link="left_wheel"/>
        <origin xyz="0 0.175 0" rpy="-1.57079633 0 0"/>
        <axis xyz="0 0 1"/>
    </joint>

    <link name="left_wheel">
        <visual>
            <geometry>
                <cylinder length="0.04" radius="0.05" />/>
            </geometry>
            <material name="blue"/>
        </visual>
        <collision>
            <geometry>
                <cylinder length="0.04" radius="0.05" />/>
            </geometry>
        </collision>
    </link>
    
     <!-- RIGHT WHEEL -->

    <joint name="right_wheel_joint" type="continuous">
        <parent link="base_link"/>
        <child link="right_wheel"/>
        <origin xyz="0 -0.175 0" rpy="-1.57079633 0 0"/>
        <axis xyz="0 0 1"/>
    </joint>

    <link name="right_wheel">
        <visual>
            <geometry>
                <cylinder length="0.04" radius="0.05" />/>
            </geometry>
            <material name="blue"/>
        </visual>
         <collision>
            <geometry>
                <cylinder length="0.04" radius="0.05" />/>
            </geometry>
            <material name="blue"/>
        </collision>
     </link>
    
    <!-- SPHERE WHEEL -->

    <joint name="sphere_wheel_joint" type="fixed">
        <parent link="chassis"/>
        <child link="sphere_wheel"/>
        <origin xyz="0.24 0 0" rpy="0 0 0"/>
    </joint>

    <link name="sphere_wheel">
        <visual>
            <geometry>
                <sphere radius="0.05" />
            </geometry>
            <material name="black"/>
        </visual>
        <collision>
            <geometry>
                <sphere radius="0.05" />
            </geometry>
            <material name="black"/>
        </collision>
    </link>
    <!-- Lidar link -->
    
    <link name="lidar_link">   
       <visual>
            <geometry>
                <cylinder length="0.04" radius="0.05" />/>
            </geometry>
            <material name="purple"/>
        </visual>
        <collision>
            <geometry>
                <cylinder length="0.04" radius="0.05" />/>
            </geometry>
        </collision>
     </link>
      <joint name="laser_joint" type="fixed">
        <parent link="chassis"/>
        <child link="lidar_link"/>
        <origin xyz="0.24 0 0.175" rpy="0 0 0"/>
    </joint>
      
</robot>
    